<mujoco>
  <option gravity="0 0 0" />
   <worldbody>
      <light diffuse=".5 .5 .5" pos="0 0 10" dir="0 0 -1"/>
      <geom type="plane" size="2 2 0.1" rgba="1 1 1 1"/>
      <body pos="0.5 0 0.1" euler="0 90 0">
         <joint name="joint0" type="hinge" pos="0 0 -0.5" axis="-1 0 0"/>
         <geom type="cylinder" size="0.05 0.5" mass="1.0" rgba="0.3 0.3 0.3 1"/>
         <body pos="0 0 1" euler="0 0 0">
            <joint name="joint1" type="hinge" axis="-1 0 0" pos="0 0 -0.5"/>
            <geom type="cylinder" size="0.05 0.5" mass="1.0" rgba="0.3 0.3 0.3 1"/>
            <site name="tip" size="0.1" pos="0 0 0.5"/>
         </body>
      </body>
   </worldbody>
   <sensor>
     <framepos objtype="site" objname="tip"/>
   </sensor>
   <actuator>
      <motor name="joint0_torque_servo" joint="joint0" gear="1" ctrllimited="true" ctrlrange="-100 100"/>
      <position name="joint0_position_servo" joint="joint0" kp="10"/>
      <velocity name="joint0_velocity_servo" joint="joint0" kv="10"/>
      <motor name="joint1_torque_servo" joint="joint1" gear="1" ctrllimited="true" ctrlrange="-100 100"/>
      <position name="joint1_position_servo" joint="joint1" kp="10"/>
      <velocity name="joint1_velocity_servo" joint="joint1" kv="10"/>
   </actuator>
</mujoco>
